<?xml version='1.0' encoding='utf-8'?>
<robot name="generated_robot">
  <link name="dummy_base" />
  <joint name="dummy_joint" type="fixed">
    <parent link="dummy_base"/>
    <child link="base_link"/>
    <origin xyz="0 0 0" rpy="0 0 0"/>
  </joint>
  <link name="base_link">
    <inertial>
      <origin xyz="0 0 0.005" rpy="0 0 0" />
      <mass value="0.20722675" />
      <inertia ixx="0.00044381063" iyy="0.00044381063" izz="0.00088416748" ixy="0" ixz="0" iyz="0" />
    </inertial>
    <visual>
      <origin xyz="0 0 0" rpy="1.5707963 0 0" />
      <geometry>
        <mesh filename="package://robot_arm_description/meshes/part_001_solid_001.stl" scale="0.001 0.001 0.001" />
      </geometry>
    </visual>
    <collision>
      <origin xyz="0 0 0" rpy="1.5707963 0 0" />
      <geometry>
        <mesh filename="package://robot_arm_description/meshes/part_001_solid_001.stl" scale="0.001 0.001 0.001" />
      </geometry>
    </collision>
  </link>
  <link name="link_1">
    <inertial>
      <origin xyz="-7.77359e-05 1.085663e-05 0.052" rpy="0 0 0" />
      <mass value="0.75222554" />
      <inertia ixx="0.0014611179" iyy="0.0014603677" izz="0.0014319537" ixy="0" ixz="0" iyz="0" />
    </inertial>
    <visual>
      <origin xyz="0 0 -0.0125" rpy="1.5707963 0 0" />
      <geometry>
        <mesh filename="package://robot_arm_description/meshes/part_004_solid_004.stl" scale="0.001 0.001 0.001" />
      </geometry>
    </visual>
    <collision>
      <origin xyz="0 0 -0.0125" rpy="1.5707963 0 0" />
      <geometry>
        <mesh filename="package://robot_arm_description/meshes/part_004_solid_004.stl" scale="0.001 0.001 0.001" />
      </geometry>
    </collision>
  </link>
  <link name="link_2">
    <inertial>
      <origin xyz="-0.17305284 -0.045749999 0.078439232" rpy="0 0 0" />
      <mass value="0.92159971" />
      <inertia ixx="0.0036781725" iyy="0.016267603" izz="0.01272767" ixy="0" ixz="0" iyz="0" />
    </inertial>
    <visual>
      <origin xyz="0 0.02095 -0.068" rpy="1.5707963 0 0" />
      <geometry>
        <mesh filename="package://robot_arm_description/meshes/part_002_solid_002.stl" scale="0.001 0.001 0.001" />
      </geometry>
    </visual>
    <collision>
      <origin xyz="0 0.02095 -0.068" rpy="1.5707963 0 0" />
      <geometry>
        <mesh filename="package://robot_arm_description/meshes/part_002_solid_002.stl" scale="0.001 0.001 0.001" />
      </geometry>
    </collision>
  </link>
  <link name="link_3">
    <inertial>
      <origin xyz="0.045797883 0.04535 -0.023750007" rpy="0 0 0" />
      <mass value="2.40023" />
      <inertia ixx="0.006297151" iyy="0.012367358" izz="0.0093611186" ixy="0" ixz="0" iyz="0" />
    </inertial>
    <visual>
      <origin xyz="0.34610569 0.0517 -0.22487846" rpy="1.5707963 0 0" />
      <geometry>
        <mesh filename="package://robot_arm_description/meshes/part_003_solid_003.stl" scale="0.001 0.001 0.001" />
      </geometry>
    </visual>
    <collision>
      <origin xyz="0.34610569 0.0517 -0.22487846" rpy="1.5707963 0 0" />
      <geometry>
        <mesh filename="package://robot_arm_description/meshes/part_003_solid_003.stl" scale="0.001 0.001 0.001" />
      </geometry>
    </collision>
  </link>
  <link name="camera">
    <inertial>
      <origin xyz="-0.28386569 0.0535 0.26287846" rpy="0 0 0" />
      <mass value="0.062997497" />
      <inertia ixx="8.8301445e-06" iyy="3.3693688e-05" izz="3.3693693e-05" ixy="0" ixz="0" iyz="0" />
    </inertial>
    <visual>
      <origin xyz="0 0 0" rpy="1.5707963 0 0" />
      <geometry>
        <mesh filename="package://robot_arm_description/meshes/part_010_solid_010.stl" scale="0.001 0.001 0.001" />
      </geometry>
    </visual>
    <collision>
      <origin xyz="0 0 0" rpy="1.5707963 0 0" />
      <geometry>
        <mesh filename="package://robot_arm_description/meshes/part_010_solid_010.stl" scale="0.001 0.001 0.001" />
      </geometry>
    </collision>
  </link>
  <link name="link_4">
    <inertial>
      <origin xyz="0.13742708 -0.003 9.55e-10" rpy="0 0 0" />
      <mass value="1.6739517" />
      <inertia ixx="0.0021649777" iyy="0.010966021" izz="0.010769611" ixy="0" ixz="0" iyz="0" />
    </inertial>
    <visual>
      <origin xyz="0.20710569 0 -0.16487846" rpy="1.5707963 0 0" />
      <geometry>
        <mesh filename="package://robot_arm_description/meshes/part_006_solid_006.stl" scale="0.001 0.001 0.001" />
      </geometry>
    </visual>
    <collision>
      <origin xyz="0.20710569 0 -0.16487846" rpy="1.5707963 0 0" />
      <geometry>
        <mesh filename="package://robot_arm_description/meshes/part_006_solid_006.stl" scale="0.001 0.001 0.001" />
      </geometry>
    </collision>
  </link>
  <link name="link_5">
    <inertial>
      <origin xyz="6.6e-10 -0.041 4.77e-09" rpy="0 0 0" />
      <mass value="0.095084454" />
      <inertia ixx="6.3389636e-05" iyy="2.5355854e-05" izz="6.3389636e-05" ixy="0" ixz="0" iyz="0" />
    </inertial>
    <visual>
      <origin xyz="-0.042894309 -0.038 -0.16487846" rpy="1.5707963 0 0" />
      <geometry>
        <mesh filename="package://robot_arm_description/meshes/part_005_solid_005.stl" scale="0.001 0.001 0.001" />
      </geometry>
    </visual>
    <collision>
      <origin xyz="-0.042894309 -0.038 -0.16487846" rpy="1.5707963 0 0" />
      <geometry>
        <mesh filename="package://robot_arm_description/meshes/part_005_solid_005.stl" scale="0.001 0.001 0.001" />
      </geometry>
    </collision>
  </link>
  <link name="link_6">
    <inertial>
      <origin xyz="0.030000001 0 4.77e-09" rpy="0 0 0" />
      <mass value="0.16141715" />
      <inertia ixx="0.00021218407" iyy="6.7849009e-05" izz="0.00024118535" ixy="0" ixz="0" iyz="0" />
    </inertial>
    <visual>
      <origin xyz="-0.046894309 0.003 -0.16487846" rpy="1.5707963 0 0" />
      <geometry>
        <mesh filename="package://robot_arm_description/meshes/part_007_solid_007.stl" scale="0.001 0.001 0.001" />
      </geometry>
    </visual>
    <collision>
      <origin xyz="-0.046894309 0.003 -0.16487846" rpy="1.5707963 0 0" />
      <geometry>
        <mesh filename="package://robot_arm_description/meshes/part_007_solid_007.stl" scale="0.001 0.001 0.001" />
      </geometry>
    </collision>
  </link>
  <link name="right_gripper">
    <inertial>
      <origin xyz="0.034372258 -0.00010536384 -0.0099999952" rpy="0 0 0" />
      <mass value="0.071346324" />
      <inertia ixx="9.9848345e-06" iyy="6.7599466e-05" izz="7.2827879e-05" ixy="0" ixz="0" iyz="0" />
    </inertial>
    <visual>
      <origin xyz="-0.086894309 0.043 -0.17387846" rpy="1.5707963 0 0" />
      <geometry>
        <mesh filename="package://robot_arm_description/meshes/part_008_solid_008.stl" scale="0.001 0.001 0.001" />
      </geometry>
    </visual>
    <collision>
      <origin xyz="-0.086894309 0.043 -0.17387846" rpy="1.5707963 0 0" />
      <geometry>
        <mesh filename="package://robot_arm_description/meshes/part_008_solid_008.stl" scale="0.001 0.001 0.001" />
      </geometry>
    </collision>
  </link>
  <link name="left_gripper">
    <inertial>
      <origin xyz="0.034372258 0.00010536384 -0.0099999952" rpy="0 0 0" />
      <mass value="0.071346324" />
      <inertia ixx="9.9848345e-06" iyy="6.7599466e-05" izz="7.2827879e-05" ixy="0" ixz="0" iyz="0" />
    </inertial>
    <visual>
      <origin xyz="-0.086894309 -0.037 -0.17387846" rpy="1.5707963 0 0" />
      <geometry>
        <mesh filename="package://robot_arm_description/meshes/part_009_solid_009.stl" scale="0.001 0.001 0.001" />
      </geometry>
    </visual>
    <collision>
      <origin xyz="-0.086894309 -0.037 -0.17387846" rpy="1.5707963 0 0" />
      <geometry>
        <mesh filename="package://robot_arm_description/meshes/part_009_solid_009.stl" scale="0.001 0.001 0.001" />
      </geometry>
    </collision>
  </link>
  <joint name="link_1_joint" type="continuous">
    <origin xyz="0 0 0.0125" rpy="0 0 0" />
    <parent link="base_link" />
    <child link="link_1" />
    <axis xyz="0 0 -1" />
    <limit effort="10" velocity="5" />
  </joint>
  <joint name="link_2_joint" type="revolute">
    <origin xyz="0 -0.02095 0.0555" rpy="0 0 0" />
    <parent link="link_1" />
    <child link="link_2" />
    <axis xyz="0 1 0" />
    <limit lower="-0.75" upper="3.05" effort="10" velocity="5" />
  </joint>
  <joint name="link_3_joint" type="continuous">
    <origin xyz="-0.34610569 -0.03075 0.15687846" rpy="0 0 0" />
    <parent link="link_2" />
    <child link="link_3" />
    <axis xyz="0 1 0" />
    <limit effort="10" velocity="5" />
  </joint>
  <joint name="camera_joint" type="fixed">
    <origin xyz="0.34610569 0.0517 -0.22487846" rpy="0 0 0" />
    <parent link="link_3" />
    <child link="camera" />
  </joint>
  <joint name="link_4_joint" type="continuous">
    <origin xyz="-0.20710569 0 0.16487846" rpy="0 0 0" />
    <parent link="camera" />
    <child link="link_4" />
    <axis xyz="1 0 0" />
    <limit effort="10" velocity="5" />
  </joint>
  <joint name="link_5_joint" type="revolute">
    <origin xyz="0.25 0.038 0" rpy="0 0 0" />
    <parent link="link_4" />
    <child link="link_5" />
    <axis xyz="0 1 0" />
    <limit lower="-1.57" upper="1.57" effort="10" velocity="5" />
  </joint>
  <joint name="link_6_joint" type="continuous">
    <origin xyz="0.004 -0.041 0" rpy="0 0 0" />
    <parent link="link_5" />
    <child link="link_6" />
    <axis xyz="1 0 0" />
    <limit effort="10" velocity="5" />
  </joint>
  <joint name="right_gripper_joint" type="revolute">
    <origin xyz="0.04 -0.04 0.009" rpy="0 0 0" />
    <parent link="link_6" />
    <child link="right_gripper" />
    <axis xyz="0 0 1" />
    <limit lower="-1.57" upper="1.57" effort="10" velocity="5" />
  </joint>
  <joint name="left_gripper_joint" type="revolute">
    <origin xyz="0.04 0.04 0.009" rpy="0 0 0" />
    <parent link="link_6" />
    <child link="left_gripper" />
    <axis xyz="0 0 -1" />
    <limit lower="-1.57" upper="1.57" effort="10" velocity="5" />
  </joint>
</robot>